<?xml version="1.0"?>
<robot xmlns:xacro="http://www.ros.org/wiki/xacro" >

    <xacro:include filename="inertial_macros.xacro"/>

    <material name="white">
        <color rgba="1 1 1 1" />
    </material>

    <material name="orange">
        <color rgba="1 0.3 0.1 1"/>
    </material>

    <material name="blue">
        <color rgba="0.2 0.2 1 1"/>
    </material>

    <material name="black">
        <color rgba="0 0 0 1"/>
    </material>

    <material name="red">
        <color rgba="0.8 0 0 0.8"/>
    </material>

    <!-- BASE LINK -->

    <link name="base_link">
    </link>

    <!-- BASE_FOOTPRINT LINK -->

    <joint name="base_footprint_joint" type="fixed">
        <parent link="base_link"/>
        <child link="base_footprint"/>
        <origin xyz="0 0 0" rpy="0 0 0"/>
    </joint>

    <link name="base_footprint">
    </link>

    <!-- CHASSIS LINK -->

    <joint name="chassis_joint" type="fixed">
        <parent link="base_link"/>
        <child link="chassis"/>
        <origin xyz="-0.35 0 0"/>
    </joint>

    <link name="chassis">
        <visual>
            <origin xyz="0.35 0 0.225"/>
            <geometry>
                <box size="0.7 0.6 0.45"/>
            </geometry>
            <material name="white"/>
        </visual>
        <collision>
            <origin xyz="0.35 0 0.225"/>
            <geometry>
                <box size="0.7 0.6 0.45"/>
            </geometry>
        </collision>
        <xacro:inertial_box mass="30" x="0.7" y="0.6" z="0.45">
            <origin xyz="0.35 0 0.225" rpy="0 0 0"/>
        </xacro:inertial_box>
    </link>

    <gazebo reference="chassis">
        <material>Gazebo/White</material>
        <mu1 value="0.001"/>
        <mu2 value="0.001"/>
    </gazebo>
    
    <!-- LEFT BACK WHEEL LINK -->

    <joint name="left_back_wheel_joint" type="continuous">
        <parent link="base_link"/>
        <child link="left_back_wheel"/>
        <origin xyz="0.25 0.325 0" rpy="-${pi/2} 0 0" />
        <axis xyz="0 0 1"/>
        <limit effort="10000" velocity="1000"/>
        <dynamics damping="1.0" friction="1.0"/>
    </joint>

    <link name="left_back_wheel">
        <visual>
            <geometry>
                <cylinder radius="0.1" length="0.07"/>
            </geometry>
            <material name="blue"/>
        </visual>
        <collision>
            <geometry>
                <sphere radius="0.1"/>
            </geometry>
        </collision>
        <xacro:inertial_cylinder mass="1" length="0.07" radius="0.1">
            <origin xyz="0 0 0" rpy="0 0 0"/>
        </xacro:inertial_cylinder>
    </link>

    <gazebo reference="left_back_wheel">
        <material>Gazebo/Blue</material>
  
    </gazebo>

    <!-- RIGHT BACK WHEEL LINK -->

    <joint name="right_back_wheel_joint" type="continuous">
        <parent link="base_link"/>
        <child link="right_back_wheel"/>
        <origin xyz="0.25 -0.325 0" rpy="${pi/2} 0 0" />
        <axis xyz="0 0 -1"/>
        <limit effort="10000" velocity="1000"/>
        <dynamics damping="1.0" friction="1.0"/>
    </joint>

    <link name="right_back_wheel">
        <visual>
            <geometry>
                <cylinder radius="0.1" length="0.07"/>
            </geometry>
            <material name="blue"/>
        </visual>
        <collision>
            <geometry>
                <sphere radius="0.1"/>
            </geometry>
        </collision>
        <xacro:inertial_cylinder mass="1" length="0.07" radius="0.1">
            <origin xyz="0 0 0" rpy="0 0 0"/>
        </xacro:inertial_cylinder>
    </link>

    <gazebo reference="right_back_wheel">
        <material>Gazebo/Blue</material>

    </gazebo>
    

    <!-- LEFT FRONT WHEEL LINK -->

    <joint name="left_front_wheel_joint" type="continuous">
        <parent link="base_link"/>
        <child link="left_front_wheel"/>
        <origin xyz="-0.25 0.325 0" rpy="-${pi/2} 0 0" />
        <axis xyz="0 0 1"/>
        <limit effort="10000" velocity="1000"/>
        <dynamics damping="1.0" friction="1.0"/>
    </joint>

    <link name="left_front_wheel">
        <visual>
            <geometry>
                <cylinder radius="0.1" length="0.07"/>
            </geometry>
            <material name="blue"/>
        </visual>
        <collision>
            <geometry>
                <sphere radius="0.1"/>
            </geometry>
        </collision>
        <xacro:inertial_cylinder mass="1" length="0.07" radius="0.1">
            <origin xyz="0 0 0" rpy="0 0 0"/>
        </xacro:inertial_cylinder>
    </link>

    <gazebo reference="left_front_wheel">
        <material>Gazebo/Blue</material>
        <mu1 value="0.001"/>
        <mu2 value="0.001"/>
    </gazebo>

   <!-- RIGHT FRONT WHEEL LINK --> 

    <joint name="right_front_wheel_joint" type="continuous">
        <parent link="base_link"/>
        <child link="right_front_wheel"/>
        <origin xyz="-0.25 -0.325 0" rpy="${pi/2} 0 0" />
        <axis xyz="0 0 -1"/>
        <limit effort="10000" velocity="1000"/>
        <dynamics damping="1.0" friction="1.0"/>
    </joint>

    <link name="right_front_wheel">
        <visual>
            <geometry>
                <cylinder radius="0.1" length="0.07"/>
            </geometry>
            <material name="blue"/>
        </visual>
        <collision>
            <geometry>
                <sphere radius="0.1"/>
            </geometry>
        </collision>
        <xacro:inertial_cylinder mass="1" length="0.07" radius="0.1">
            <origin xyz="0 0 0" rpy="0 0 0"/>
        </xacro:inertial_cylinder>
    </link>
    
    <gazebo reference="right_front_wheel">
        <material>Gazebo/Blue</material>
        <mu1 value="0.001"/>
        <mu2 value="0.001"/>
    </gazebo>


</robot>