<?xml version="1.0"?>
<robot xmlns:xacro="http://www.ros.org/wiki/xacro" >

    <xacro:include filename="inertial_macros.xacro"/>

    <material name="white">
        <color rgba="0.85 0.9 0.8 1" />
    </material>

    <material name="orange">
        <color rgba="1 0.3 0.1 1"/>
    </material>

    <material name="blue">
        <color rgba="0.2 0.2 1 1"/>
    </material>

    <material name="black">
        <color rgba="0.1 0.05 0.1 1"/>
    </material>

    <material name="red">
        <color rgba="1 0 0 1"/>
    </material>

    <!-- BASE LINK -->

    <link name="base_link">

    </link>

    <!-- BASE_FOOTPRINT LINK -->

    <joint name="base_footprint_joint" type="fixed">
        <parent link="base_link"/>
        <child link="base_footprint"/>
        <origin xyz="0 0 0" rpy="0 0 0"/>
    </joint>

    <link name="base_footprint">
    </link>

    <!-- CHASSIS LINK -->

    <joint name="chassis_joint" type="fixed">
        <parent link="base_link"/>
        <child link="chassis"/>
        <origin xyz="-0.1 0 0"/>
    </joint>

    <link name="chassis">
        <visual>
            <origin xyz="0.35 0 0.225"/>
            <geometry>
                <box size="0.65 0.65 0.45"/>
            </geometry>
            <material name="black"/>
        </visual>
        <collision>
            <origin xyz="0.315 0 0.225"/>
            <geometry>
                <box size="0.65 0.65 0.45"/>
            </geometry>
        </collision>
        <xacro:inertial_box mass="6" x="0.65" y="0.65" z="0.45">
            <origin xyz="0.315 0 0.225" rpy="0 0 0"/>
        </xacro:inertial_box>
    </link>

    <gazebo reference="chassis">
        <material>Gazebo/Black</material>
    </gazebo>

    <!-- LEFT WHEEL LINK -->

    <joint name="left_back_wheel_joint" type="continuous">
        <parent link="base_link"/>
        <child link="left_back_wheel"/>
        <origin xyz="0.10 0.33 0" rpy="-${pi/2} 0 0" />
        <axis xyz="0 0 1"/>
    </joint>

    <link name="left_back_wheel">
        <visual>
            <geometry>
                <cylinder radius="0.07" length="0.05"/>
            </geometry>
            <material name="red"/>
        </visual>
        <collision>
            <geometry>
                <sphere radius="0.07"/>
            </geometry>
        </collision>
        <xacro:inertial_cylinder mass="2" length="0.05" radius="0.07">
            <origin xyz="0 0 0" rpy="0 0 0"/>
        </xacro:inertial_cylinder>
    </link>

    <gazebo reference="left_back_wheel">
        <material>Gazebo/Red</material>
    </gazebo>


    <!-- RIGHT WHEEL LINK -->

    <joint name="right_back_wheel_joint" type="continuous">
        <parent link="base_link"/>
        <child link="right_back_wheel"/>
        <origin xyz="0.10 -0.33 0" rpy="${pi/2} 0 0" />
        <axis xyz="0 0 -1"/>
    </joint>

    <link name="right_back_wheel">
        <visual>
            <geometry>
                <cylinder radius="0.07" length="0.05"/>
            </geometry>
            <material name="red"/>
        </visual>
        <collision>
            <geometry>
                <sphere radius="0.07"/>
            </geometry>
        </collision>
    <xacro:inertial_cylinder mass="2" length="0.05" radius="0.07">
            <origin xyz="0 0 0" rpy="0 0 0"/>
        </xacro:inertial_cylinder>
    </link>

    <gazebo reference="right_back_wheel">
        <material>Gazebo/Red</material>
    </gazebo>


    <!-- CASTER WHEEL LINK -->

    <joint name="caster_wheel_joint" type="fixed">
        <parent link="chassis"/>
        <child link="caster_wheel"/>
        <origin xyz="0.60 0 0"/>
    </joint>


    <link name="caster_wheel">
        <visual>
            <geometry>
                <sphere radius="0.07"/>
            </geometry>
            <material name="orange"/>
        </visual>
        <collision>
            <geometry>
                <sphere radius="0.07"/>
            </geometry>
        </collision>
        <xacro:inertial_sphere mass="0.3" radius="0.07">
            <origin xyz="0 0 0" rpy="0 0 0"/>
        </xacro:inertial_sphere>
    </link>

    <gazebo reference="caster_wheel">
        <material>Gazebo/Black</material>
        <mu1 value="0.02"/>
        <mu2 value="0.02"/>
    </gazebo>

</robot>